Workbook

Sheet Лист1
A1: Дата | B1: Территория | C1: Товарооборот, шт | D1: Товарооборот, руб | E1: Количество складов | F1: Количество заказов | G1: Количество клиентов | H1: Товарооборот на склад | I1: Неделя
A2: 43982 | B2: Самара | C2: 7944 | D2: 623971.5 | E2: =SUMIFS(Лист2!C:C, Лист2!A:A, A2, Лист2!B:B, B2) -> 15 | F2: =SUMIFS(Лист2!D:D, Лист2!A:A, A2, Лист2!B:B, B2) -> 441 | G2: =SUMIFS(Лист2!E:E, Лист2!A:A, A2, Лист2!B:B, B2) -> 368 | H2: =D2/E2 -> 41598.1 | I2: =_xlfn.ISOWEEKNUM(A2) -> 22
A3: 43981 | B3: Самара | C3: 10029 | D3: 787101 | E3: =SUMIFS(Лист2!C:C, Лист2!A:A, A3, Лист2!B:B, B3) -> 15 | F3: =SUMIFS(Лист2!D:D, Лист2!A:A, A3, Лист2!B:B, B3) -> 490 | G3: =SUMIFS(Лист2!E:E, Лист2!A:A, A3, Лист2!B:B, B3) -> 409 | H3: =D3/E3 -> 52473.4 | I3: =_xlfn.ISOWEEKNUM(A3) -> 22
A4: 43979 | B4: Самара | C4: 8536.5 | D4: 643944 | E4: =SUMIFS(Лист2!C:C, Лист2!A:A, A4, Лист2!B:B, B4) -> 15 | F4: =SUMIFS(Лист2!D:D, Лист2!A:A, A4, Лист2!B:B, B4) -> 464 | G4: =SUMIFS(Лист2!E:E, Лист2!A:A, A4, Лист2!B:B, B4) -> 390 | H4: =D4/E4 -> 42929.6 | I4: =_xlfn.ISOWEEKNUM(A4) -> 22
A5: 43967 | B5: Кемерово | C5: 38947.5 | D5: 3395892 | E5: =SUMIFS(Лист2!C:C, Лист2!A:A, A5, Лист2!B:B, B5) -> 21 | F5: =SUMIFS(Лист2!D:D, Лист2!A:A, A5, Лист2!B:B, B5) -> 2145 | G5: =SUMIFS(Лист2!E:E, Лист2!A:A, A5, Лист2!B:B, B5) -> 1947 | H5: =D5/E5 -> 161709.14 | I5: =_xlfn.ISOWEEKNUM(A5) -> 20
A6: 43970 | B6: Кемерово | C6: 31842 | D6: 2771116.5 | E6: =SUMIFS(Лист2!C:C, Лист2!A:A, A6, Лист2!B:B, B6) -> 21 | F6: =SUMIFS(Лист2!D:D, Лист2!A:A, A6, Лист2!B:B, B6) -> 1860 | G6: =SUMIFS(Лист2!E:E, Лист2!A:A, A6, Лист2!B:B, B6) -> 1704 | H6: =D6/E6 -> 131957.93 | I6: =_xlfn.ISOWEEKNUM(A6) -> 21
A7: 43968 | B7: Кемерово | C7: 32023.5 | D7: 2882458.5 | E7: =SUMIFS(Лист2!C:C, Лист2!A:A, A7, Лист2!B:B, B7) -> 21 | F7: =SUMIFS(Лист2!D:D, Лист2!A:A, A7, Лист2!B:B, B7) -> 1874 | G7: =SUMIFS(Лист2!E:E, Лист2!A:A, A7, Лист2!B:B, B7) -> 1705 | H7: =D7/E7 -> 137259.93 | I7: =_xlfn.ISOWEEKNUM(A7) -> 20
A8: 43960 | B8: Кемерово | C8: 31147.5 | D8: 2831019 | E8: =SUMIFS(Лист2!C:C, Лист2!A:A, A8, Лист2!B:B, B8) -> 21 | F8: =SUMIFS(Лист2!D:D, Лист2!A:A, A8, Лист2!B:B, B8) -> 1735 | G8: =SUMIFS(Лист2!E:E, Лист2!A:A, A8, Лист2!B:B, B8) -> 1568 | H8: =D8/E8 -> 134810.43 | I8: =_xlfn.ISOWEEKNUM(A8) -> 19
A9: 43955 | B9: Кемерово | C9: 25566 | D9: 2372310 | E9: =SUMIFS(Лист2!C:C, Лист2!A:A, A9, Лист2!B:B, B9) -> 20 | F9: =SUMIFS(Лист2!D:D, Лист2!A:A, A9, Лист2!B:B, B9) -> 1519 | G9: =SUMIFS(Лист2!E:E, Лист2!A:A, A9, Лист2!B:B, B9) -> 1372 | H9: =D9/E9 -> 118615.5 | I9: =_xlfn.ISOWEEKNUM(A9) -> 19
A10: 43950 | B10: Кемерово | C10: 29319 | D10: 2623480.5 | E10: =SUMIFS(Лист2!C:C, Лист2!A:A, A10, Лист2!B:B, B10) -> 18 | F10: =SUMIFS(Лист2!D:D, Лист2!A:A, A10, Лист2!B:B, B10) -> 1684 | G10: =SUMIFS(Лист2!E:E, Лист2!A:A, A10, Лист2!B:B, B10) -> 1528 | H10: =D10/E10 -> 145748.92 | I10: =_xlfn.ISOWEEKNUM(A10) -> 18
A11: 43953 | B11: Кемерово | C11: 29031 | D11: 2711247 | E11: =SUMIFS(Лист2!C:C, Лист2!A:A, A11, Лист2!B:B, B11) -> 18 | F11: =SUMIFS(Лист2!D:D, Лист2!A:A, A11, Лист2!B:B, B11) -> 1708 | G11: =SUMIFS(Лист2!E:E, Лист2!A:A, A11, Лист2!B:B, B11) -> 1534 | H11: =D11/E11 -> 150624.83 | I11: =_xlfn.ISOWEEKNUM(A11) -> 18
A12: 43977 | B12: Кемерово | C12: 33423 | D12: 2970330 | E12: =SUMIFS(Лист2!C:C, Лист2!A:A, A12, Лист2!B:B, B12) -> 20 | F12: =SUMIFS(Лист2!D:D, Лист2!A:A, A12, Лист2!B:B, B12) -> 2044 | G12: =SUMIFS(Лист2!E:E, Лист2!A:A, A12, Лист2!B:B, B12) -> 1863 | H12: =D12/E12 -> 148516.5 | I12: =_xlfn.ISOWEEKNUM(A12) -> 22
A13: 43952 | B13: Кемерово | C13: 32487 | D13: 3031254 | E13: =SUMIFS(Лист2!C:C, Лист2!A:A, A13, Лист2!B:B, B13) -> 18 | F13: =SUMIFS(Лист2!D:D, Лист2!A:A, A13, Лист2!B:B, B13) -> 1826 | G13: =SUMIFS(Лист2!E:E, Лист2!A:A, A13, Лист2!B:B, B13) -> 1633 | H13: =D13/E13 -> 168403 | I13: =_xlfn.ISOWEEKNUM(A13) -> 18
... A505: 43983 | B505: Новосибирск | C505: 14238 | D505: 1293219 | E505: =SUMIFS(Лист2!C:C, Лист2!A:A, A505, Лист2!B:B, B505) -> 18 | F505: =SUMIFS(Лист2!D:D, Лист2!A:A, A505, Лист2!B:B, B505) -> 923 | G505: =SUMIFS(Лист2!E:E, Лист2!A:A, A505, Лист2!B:B, B505) -> 824 | H505: =D505/E505 -> 71845.5 | I505: =_xlfn.ISOWEEKNUM(A505) -> 23

Sheet Лист2
A1: Дата | B1: Территория | C1: Количество складов | D1: Количество заказов | E1: Количество клиентов
A2: 43949 | B2: Волгоград | C2: 36 | D2: 4923 | E2: 4560
A3: 43949 | B3: Екатеринбург | C3: 31 | D3: 5465 | E3: 5096
A4: 43949 | B4: Казань | C4: 19 | D4: 1846 | E4: 1681
A5: 43949 | B5: Кемерово | C5: 18 | D5: 1539 | E5: 1404
A6: 43949 | B6: Краснодар | C6: 18 | D6: 1505 | E6: 1368
A7: 43949 | B7: Москва Восток | C7: 54 | D7: 12306 | E7: 11532
A8: 43949 | B8: Москва Запад | C8: 59 | D8: 12943 | E8: 12072
A9: 43949 | B9: Нижний Новгород | C9: 17 | D9: 1439 | E9: 1265
A10: 43949 | B10: Новосибирск | C10: 15 | D10: 636 | E10: 547
A11: 43949 | B11: Пермь | C11: 15 | D11: 780 | E11: 690
A12: 43949 | B12: Санкт-Петербург Север | C12: 125 | D12: 20914 | E12: 19479
A13: 43949 | B13: Санкт-Петербург Юг | C13: 128 | D13: 16450 | E13: 15320
... A505: 43983 | B505: Уфа | C505: 6 | D505: 237 | E505: 175

Sheet 1.1 
A3: Названия строк | B3: Сумма по полю Товарооборот, руб | C3: Среднее по полю Товарооборот на склад
A4: 18
A5: Волгоград | B5: 36934095 | C5: 170991.18
A6: Екатеринбург | B6: 42828758 | C6: 230262.14
A7: Казань | B7: 17828216 | C7: 150976.88
A8: Кемерово | B8: 16029680 | C8: 144795.51
A9: Краснодар | B9: 13955985 | C9: 124681.15
A10: Москва Восток | B10: 130713645 | C10: 403437.18
A11: Москва Запад | B11: 136791225 | C11: 386415.89
A12: Нижний Новгород | B12: 13145966 | C12: 118689.08
A13: Новосибирск | B13: 5746024.5 | C13: 63844.717
A14: Пермь | B14: 6961020 | C14: 77344.667
A15: Ростов-на-Дону | B15: 2008809 | C15: 33480.15
A16: Санкт-Петербург Север | B16: 233059077 | C16: 310745.44
... A18: Тольятти | B18: 4531000.5 | C18: 75516.675
A19: 19
A20: Волгоград | B20: 43307156 | C20: 171853.79
A21: Екатеринбург | B21: 46366010 | C21: 213668.25
A22: Казань | B22: 20974521 | C22: 145474.52
A23: Кемерово | B23: 19479056 | C23: 135305.72
A24: Краснодар | B24: 16391856 | C24: 123247.04
A25: Москва Восток | B25: 1.5164204e+08 | C25: 401169.42
A26: Москва Запад | B26: 159695760 | C26: 386672.54
A27: Нижний Новгород | B27: 17149980 | C27: 128947.22
A28: Новосибирск | B28: 7253572.5 | C28: 69081.643
A29: Пермь | B29: 8778597 | C29: 83605.686
A30: Ростов-на-Дону | B30: 5892277.5 | C30: 56116.929
A31: Санкт-Петербург Север | B31: 2.727625e+08 | C31: 311728.58
... A33: Тольятти | B33: 6093688.5 | C33: 87052.693
A34: 20
A35: Волгоград | B35: 41300679 | C35: 163891.58
A36: Екатеринбург | B36: 47079842 | C36: 216957.79
A37: Казань | B37: 23603355 | C37: 160567.04
A38: Кемерово | B38: 19724733 | C38: 134181.86
A39: Краснодар | B39: 16732521 | C39: 125808.43
A40: Москва Восток | B40: 135813990 | C40: 359296.27
A41: Москва Запад | B41: 142825023 | C41: 340059.58
A42: Нижний Новгород | B42: 19963154 | C42: 150098.9
A43: Новосибирск | B43: 7841920.5 | C43: 71889.364
A44: Пермь | B44: 9036316.5 | C44: 86060.157
...

Sheet 1.1.а) топ3 по доле ...
A1: Неделя | B1: 23
A3: Названия строк | B3: Сумма по полю Товарооборот, руб | C3: Среднее по полю Товарооборот на склад | D3: Сумма по полю Товарооборот, руб2
A4: Москва Запад | B4: 19465372 | C4: 329921.57 | D4: 0.23037769
A5: Санкт-Петербург Север | B5: 37257840 | C5: 302909.27 | D5: 0.44095612
A6: Санкт-Петербург Юг | B6: 27770092 | C6: 216953.85 | D6: 0.32866619

Sheet 1.1.а)топ3 по товарооб на склад
A1: Неделя | B1: 23
A3: Названия строк | B3: Сумма по полю Товарооборот, руб | C3: Среднее по полю Товарооборот на склад | D3: Сумма по полю Товарооборот, руб2
A4: Москва Восток | B4: 18914194 | C4: 350262.86 | D4: 0.25006403
A5: Москва Запад | B5: 19465372 | C5: 329921.57 | D5: 0.25735113
A6: Санкт-Петербург Север | B6: 37257840 | C6: 302909.27 | D6: 0.49258484

Sheet 1.2 Диаграмма
A3: Названия строк | B3: Сумма по полю Товарооборот, руб | C3: Среднее по полю Товарооборот на склад
A4: 18 | B4: 836803032 | C4: 183538.9
A5: 19 | B5: 9.8391541e+08 | C5: 181743.54
A6: 20 | B6: 9.4726301e+08 | C6: 178616.65
A7: 21 | B7: 1.0026919e+09 | C7: 191353.01
A8: 22 | B8: 1.0556535e+09 | C8: 185990.79
A9: 23 | B9: 1.3603238e+08 | C9: 154780.08
A10: Общий итог | B10: 4.9623592e+09 | C10: 183260.14
